Workbook

Sheet Conversion Rates
A1: CONVERSION RATES — In Funnel Order
A2: Edit any cell in columns C or D. These flow through to the Projections tab and both Trackers.
A4: # | B4: Funnel Step | C4: Phase 1 | D4: Phase 2 | E4: Basis / Notes
A5: 1 | B5: Show Rate (webinar attendance) | C5: 0.3 | D5: 0.5 | E5: % of registrations
A6: 2 | B6: Thank You Page Call Booking | C6: 0.05 | D6: 0.05 | E6: % of registrations
A7: 3 | B7: Email Call Booking | C7: 0.01 | D7: 0.01 | E7: % of registrations
A8: 4 | B8: Phone Call Booking | C8: 0.03 | D8: 0.03 | E8: % of registrations
A9: 5 | B9: Low Ticket Conversion (sale rate) | C9: 0.1 | D9: 0.15 | E9: % of attendees who buy
A10: 6 | B10: Post-LTO Call Booking | C10: 0.5 | D10: 0.5 | E10: % of LTO buyers who book the call
A11: 7 | B11: Hammer Them Direct Call Booking | C11: 0 | D11: 0.05 | E11: Phase 2 only — % of registrations
A12: 8 | B12: Call Show Rate | C12: 0.5 | D12: 0.6 | E12: % of booked calls held
A13: 9 | B13: Sales Close Rate | C13: 0.25 | D13: 0.3 | E13: % of held calls that close
A15: Yellow cells = editable inputs

Sheet Pricing & Budget
A1: PRICING, BUDGET & REFUNDS
A2: All non-rate inputs live here. Edit any value in column C or D.
A4: Metric | C4: Phase 1 | D4: Phase 2 | E4: Notes
A6: PRICING
A7: Low-Ticket Offer Price | C7: 97 | D7: 97 | E7: $ per LTO sale
A8: [DEPRECATED — see HT Sales Structure below] | E8: Now modeled by LIL + Annual structure
A9: [DEPRECATED — see HT Sales Structure below] | E9: Now derived from renewal rate × contract length
A11: MONTHLY AD BUDGET (CAD)
A12: Direct Response Budget | C12: 10000 | D12: 8000 | E12: Phase 1 = all DR; Phase 2 = DR portion only
A13: Hammer Them Budget | C13: 0 | D13: 2000 | E13: Phase 2 only — content/warming spend
A14: Cost Per Lead | C14: 10 | D14: 20 | E14: Higher in Phase 2 (quality-optimized)
A15: Total Monthly Budget (calc) | C15: =C12+C13 | D15: =D12+D13 | E15: Auto-calculated
A17: REFUND RATES
A18: LTO Refund Rate % | C18: 0.05 | D18: 0.05 | E18: % of LT sales refunded — haircuts LT revenue
A19: MRR/HT Refund Rate % | C19: 0.05 | D19: 0.05 | E19: % of new MRR refunded — haircuts MRR & LTV
A21: HIGH-TICKET SALES STRUCTURE (Love It or Leave It + Annual)
A22: LIL Upfront Price (USD) | C22: 4000 | D22: 4000 | E22: First-60-day upfront option
A23: LIL Monthly Option Price (USD/mo) | C23: 2500 | D23: 2500 | E23: Alternative to upfront, paid monthly during LIL
A24: LIL Monthly Option Length (months) | C24: 2 | D24: 2 | E24: 60-day LIL = 2 months
A25: % Choosing Upfront Option | C25: 0.8 | D25: 0.8 | E25: Most clients pay upfront ($4k vs $5k total)
A26: Post-LIL Annual Monthly Price (USD) | C26: 2000 | D26: 2000 | E26: Monthly rate during 12-month annual contract
A27: Post-LIL Annual Contract Length | C27: 12 | D27: 12 | E27: Months in annual commitment
A28: Post-LIL Renewal Rate % | C28: 0.5 | D28: 0.5 | E28: % of LIL grads who sign 12-month annual

Sheet Currency
A1: CURRENCY
A2: Used to convert USD high-ticket revenue to CAD.
A4: Metric | B4: Rate | C4: Notes
A5: USD to CAD Exchange Rate | B5: 1.36 | C5: (editable — applies to all USD→CAD conversions)

Sheet Projections
A1: MONTHLY PROJECTIONS
A2: All numbers calculated from inputs on the Conversion Rates, Pricing & Budget, and Currency tabs.
A4: Metric | B4: Phase 1: DR Only | C4: Phase 2: DR + HT | D4: Difference
A6: BUDGET & REGISTRATIONS
A7: Total Monthly Budget (CAD) | B7: ='Pricing & Budget'!C15 | C7: ='Pricing & Budget'!D15 | D7: =C7-B7
A8: Cost Per Lead | B8: ='Pricing & Budget'!C14 | C8: ='Pricing & Budget'!D14 | D8: =C8-B8
A9: Monthly Registrations | B9: =B7/B8 | C9: =C7/C8 | D9: =C9-B9
A11: WEBINAR FUNNEL
A12: Show Rate % | B12: ='Conversion Rates'!C5 | C12: ='Conversion Rates'!D5 | D12: =C12-B12
A13: Monthly Attendees | B13: =B9*B12 | C13: =C9*C12 | D13: =C13-B13
A15: LOW-TICKET SALES
A16: LT Conversion % | B16: ='Conversion Rates'!C9 | C16: ='Conversion Rates'!D9 | D16: =C16-B16
A17: Monthly LT Sales | B17: =B13*B16 | C17: =C13*C16 | D17: =C17-B17
A18: LTO Price (USD) | B18: ='Pricing & Budget'!C7 | C18: ='Pricing & Budget'!D7 | D18: =C18-B18
A19: LTO Refund Rate | B19: ='Pricing & Budget'!C18 | C19: ='Pricing & Budget'!D18 | D19: =C19-B19
A20: LT Revenue (CAD, net of refunds) | B20: =B17*B18*B45*(1-B19) | C20: =C17*C18*C45*(1-C19) | D20: =C20-B20
A22: BOOKED CALLS — From Webinar Funnel
A23: Thank You Page Calls | B23: =B9*'Conversion Rates'!C6 | C23: =C9*'Conversion Rates'!D6 | D23: =C23-B23
A24: Email Calls | B24: =B9*'Conversion Rates'!C7 | C24: =C9*'Conversion Rates'!D7 | D24: =C24-B24
A25: Phone Calls | B25: =B9*'Conversion Rates'!C8 | C25: =C9*'Conversion Rates'!D8 | D25: =C25-B25
A26: Post-LTO Calls | B26: =B17*'Conversion Rates'!C10 | C26: =C17*'Conversion Rates'!D10 | D26: =C26-B26
A27: Webinar Calls Subtotal | B27: =SUM(B23:B26) | C27: =SUM(C23:C26) | D27: =C27-B27
A29: BOOKED CALLS — Direct from Hammer Them (Phase 2 only)
A30: Direct HT Calls | B30: =B9*'Conversion Rates'!C11 | C30: =C9*'Conversion Rates'!D11 | D30: =C30-B30
A32: TOTAL BOOKED CALLS | B32: =B27+B30 | C32: =C27+C30 | D32: =C32-B32
A34: HELD CALLS & CLOSES
A35: Call Show Rate % | B35: ='Conversion Rates'!C12 | C35: ='Conversion Rates'!D12 | D35: =C35-B35
A36: Calls Held | B36: =B32*B35 | C36: =C32*C35 | D36: =C36-B36
A37: Sales Close Rate % | B37: ='Conversion Rates'!C13 | C37: ='Conversion Rates'!D13 | D37: =C37-B37
A38: Monthly Closes | B38: =B36*B37 | C38: =C36*C37 | D38: =C38-B38
A40: PER-CLOSE ECONOMICS — LIL + Annual Contract
A41: Avg LIL Revenue per Close (USD) | B41: ='Pricing & Budget'!C25*'Pricing & Budget'!C22+(1-'Pricing & Budget'!C25)*'Pricing & Budget'!C23*'Pricing & Budget'!C24 | C41: ='Pricing & Budget'!D25*'Pricing & Budget'!D22+(1-'Pricing & Budget'!D25)*'Pricing & Budget'!D23*'Pricing & Budget'!D24 | D41: =C41-B41
A42: Avg Annual Revenue per Close (USD) | B42: ='Pricing & Budget'!C28*'Pricing & Budget'!C26*'Pricing & Budget'!C27 | C42: ='Pricing & Budget'!D28*'Pricing & Budget'!D26*'Pricing & Budget'!D27 | D42: =C42-B42
A43: Total LTV per Close (USD, gross) | B43: =B41+B42 | C43: =C41+C42 | D43: =C43-B43
A44: Month 1 Cash per Close (USD, gross) | B44: ='Pricing & Budget'!C25*'Pricing & Budget'!C22+(1-'Pricing & Budget'!C25)*'Pricing & Budget'!C23 | C44: ='Pricing & Budget'!D25*'Pricing & Budget'!D22+(1-'Pricing & Budget'!D25)*'Pricing & Budget'!D23 | D44: =C44-B44
A45: Exchange Rate (USD→CAD) | B45: =Currency!B5 | C45: =Currency!B5 | D45: =C45-B45
A46: HT Refund Rate | B46: ='Pricing & Budget'!C19 | C46: ='Pricing & Budget'!D19 | D46: =C46-B46
A47: Total LTV per Close (CAD, net) | B47: =B43*B45*(1-B46) | C47: =C43*C45*(1-C46) | D47: =C47-B47
A48: Month 1 Cash per Close (CAD, net) | B48: =B44*B45*(1-B46) | C48: =C44*C45*(1-C46) | D48: =C48-B48
A50: MONTHLY CASH & REVENUE (from new closes this month)
...

Sheet Phase 1 Tracker
A1: PHASE 1 TRACKER: Direct Response Only
A3: Week # | B3: Week Starting | C3: Ad Spend ($) | D3: Registrations | E3: CPL ($) | F3: Webinar Attendees | G3: Show Rate % | H3: Low-Ticket Sales | I3: LT Conv % | J3: LT Revenue (CAD) | K3: Calls - Thank You Page | L3: Calls - Email/Phone | M3: Calls - Post-LTO | N3: Total Calls Booked | O3: Calls Held | P3: Closes | Q3: Close Rate % | R3: Cash Collected M1 ($) | S3: Cumulative Cash ($) | T3: Status | U3: Notes
A4: 1 | B4: Week 1 | E4: =IF(D4=0,0,C4/D4) | G4: =IF(D4=0,0,F4/D4) | I4: =IF(F4=0,0,H4/F4) | J4: =H4*'Pricing & Budget'!$C$7*Currency!$B$5*(1-'Pricing & Budget'!$C$18) | N4: =K4+L4+M4 | O4: =N4*'Conversion Rates'!$C$12 | Q4: =IF(O4=0,0,P4/O4) | R4: =P4*Projections!$B$48 | S4: =R4
A5: 2 | B5: Week 2 | E5: =IF(D5=0,0,C5/D5) | G5: =IF(D5=0,0,F5/D5) | I5: =IF(F5=0,0,H5/F5) | J5: =H5*'Pricing & Budget'!$C$7*Currency!$B$5*(1-'Pricing & Budget'!$C$18) | N5: =K5+L5+M5 | O5: =N5*'Conversion Rates'!$C$12 | Q5: =IF(O5=0,0,P5/O5) | R5: =P5*Projections!$B$48 | S5: =S4+R5
A6: 3 | B6: Week 3 | E6: =IF(D6=0,0,C6/D6) | G6: =IF(D6=0,0,F6/D6) | I6: =IF(F6=0,0,H6/F6) | J6: =H6*'Pricing & Budget'!$C$7*Currency!$B$5*(1-'Pricing & Budget'!$C$18) | N6: =K6+L6+M6 | O6: =N6*'Conversion Rates'!$C$12 | Q6: =IF(O6=0,0,P6/O6) | R6: =P6*Projections!$B$48 | S6: =S5+R6
A7: 4 | B7: Week 4 | E7: =IF(D7=0,0,C7/D7) | G7: =IF(D7=0,0,F7/D7) | I7: =IF(F7=0,0,H7/F7) | J7: =H7*'Pricing & Budget'!$C$7*Currency!$B$5*(1-'Pricing & Budget'!$C$18) | N7: =K7+L7+M7 | O7: =N7*'Conversion Rates'!$C$12 | Q7: =IF(O7=0,0,P7/O7) | R7: =P7*Projections!$B$48 | S7: =S6+R7
A9: Legend: | B9: Yellow = type your data here | E9: Gray = auto-calculated

Sheet Phase 2 Tracker
A1: PHASE 2 TRACKER: Direct Response + Hammer Them
A3: Week # | B3: Week Starting | C3: DR Budget ($) | D3: HT Budget ($) | E3: Registrations | F3: CPL ($) | G3: Webinar Attendees | H3: Show Rate % | I3: Low-Ticket Sales | J3: LT Conv % | K3: LT Revenue (CAD) | L3: Calls - Thank You Page | M3: Calls - Email/Phone | N3: Calls - Post-LTO | O3: Calls - Direct HT | P3: Total Calls Booked | Q3: Calls Held | R3: Closes | S3: Close Rate % | T3: Cash Collected M1 ($) | U3: Cumulative Cash ($) | V3: Status | W3: Notes
A4: 1 | B4: Week 1 | F4: =IF(E4=0,0,(C4+D4)/E4) | H4: =IF(E4=0,0,G4/E4) | J4: =IF(G4=0,0,I4/G4) | K4: =I4*'Pricing & Budget'!$D$7*Currency!$B$5*(1-'Pricing & Budget'!$D$18) | P4: =L4+M4+N4+O4 | Q4: =P4*'Conversion Rates'!$D$12 | S4: =IF(Q4=0,0,R4/Q4) | T4: =R4*Projections!$C$48 | U4: =T4
A5: 2 | B5: Week 2 | F5: =IF(E5=0,0,(C5+D5)/E5) | H5: =IF(E5=0,0,G5/E5) | J5: =IF(G5=0,0,I5/G5) | K5: =I5*'Pricing & Budget'!$D$7*Currency!$B$5*(1-'Pricing & Budget'!$D$18) | P5: =L5+M5+N5+O5 | Q5: =P5*'Conversion Rates'!$D$12 | S5: =IF(Q5=0,0,R5/Q5) | T5: =R5*Projections!$C$48 | U5: =U4+T5
A6: 3 | B6: Week 3 | F6: =IF(E6=0,0,(C6+D6)/E6) | H6: =IF(E6=0,0,G6/E6) | J6: =IF(G6=0,0,I6/G6) | K6: =I6*'Pricing & Budget'!$D$7*Currency!$B$5*(1-'Pricing & Budget'!$D$18) | P6: =L6+M6+N6+O6 | Q6: =P6*'Conversion Rates'!$D$12 | S6: =IF(Q6=0,0,R6/Q6) | T6: =R6*Projections!$C$48 | U6: =U5+T6
A7: 4 | B7: Week 4 | F7: =IF(E7=0,0,(C7+D7)/E7) | H7: =IF(E7=0,0,G7/E7) | J7: =IF(G7=0,0,I7/G7) | K7: =I7*'Pricing & Budget'!$D$7*Currency!$B$5*(1-'Pricing & Budget'!$D$18) | P7: =L7+M7+N7+O7 | Q7: =P7*'Conversion Rates'!$D$12 | S7: =IF(Q7=0,0,R7/Q7) | T7: =R7*Projections!$C$48 | U7: =U6+T7
A9: Legend: | B9: Yellow = type your data here | E9: Gray = auto-calculated

Sheet Key Insights
A1: KEY INSIGHTS: Why Phase 2 (Hammer Them) Matters
A3: PHASE 1: Direct Response Only
A4: Budget | B4: $10k/month all to DR
A5: Registrations | B5: 450/month at $10 CPL (volume optimized)
A6: Show Rate | B6: 30% (no warming)
A7: Attendees | B7: 135/month
A8: Booked Calls | B8: 54-85/month (from webinar only)
A9: Closes | B9: 11-17/month
A10: New MRR | B10: $22-34k/month
A11: New LTV | B11: $300-460k/month
A13: PHASE 2: DR + Hammer Them
A14: Budget | B14: $8k DR + $2k HT = $10k total (same budget)
A15: Registrations | B15: 400/month at $20 CPL (quality optimized)
A16: Show Rate | B16: 50% (warmed by Hammer Them)
A17: Attendees | B17: 200/month (+48% vs Phase 1)
A18: Booked Calls | B18: 68-108/month (webinar + direct HT)
A19: Closes | B19: 14-22/month (+27% vs Phase 1)
A20: New MRR | B20: $28-44k/month (+27% vs Phase 1)
A21: New LTV | B21: $380-600k/month (+27% vs Phase 1)
A23: THE HAMMER THEM ADVANTAGE
A24: 1. Higher Show Rate | B24: Hammer Them warms registrants → 50% vs 30%
A25: 2. Direct Calls | B25: People book calls from content without attending webinar
A26: 3. Better Qualified Leads | B26: DR targets quality over volume → higher close rate
A27: 4. Same Budget | B27: No additional spend, just reallocation
A28: 5. Material Impact | B28: +27% closes, +27% MRR, +27% LTV on same $10k budget
